Workbook

Sheet Resumo da Exportação
B3: Este documento foi exportado do Numbers. Cada tabela foi convertida em uma folha do Excel. Todos os outros objetos em cada folha do Numbers foram colocados em folhas à parte. Esteja ciente de que os cálculos de fórmulas podem ser diferentes no Excel.
B7: Nome da Folha do Numbers | C7: Nome da Tabela do Numbers | D7: Nome da Planilha do Excel
B9: Acompanhamento Mar26 (2)
C10: Tabela 1 | D10: Acompanhamento Mar26 (2)
B11: Acompanhamento Abr26
C12: Tabela 1 | D12: Acompanhamento Abr26
B13: DRE Report
C14: Tabela 1 | D14: DRE Report
B15: Comparativo
C16: Tabela 1 | D16: Comparativo
B17: References
C18: Tabela 1 | D18: References

Sheet Acompanhamento Mar26 (2)
U2: 1 | V2: {=U2+1} -> 2 | W2: {=V2+1} -> 3 | X2: {=W2+1} -> 4 | Y2: {=X2+1} -> 5 | Z2: {=Y2+1} -> 6 | AA2: {=Z2+1} -> 7 | AB2: {=AA2+1} -> 8 | AC2: {=AB2+1} -> 9 | ... AY2: {=AX2+1} -> 31
B3: GREENMIX |KPIs - MAR/26
C5: FATURAMENTO | I5: PEDIDOS | O5: TICKET MÉDIO | U5: 46082 | V5: {=U5+1} -> 46083 | W5: {=V5+1} -> 46084 | X5: {=W5+1} -> 46085 | Y5: {=X5+1} -> 46086 | Z5: {=Y5+1} -> 46087 | AA5: {=Z5+1} -> 46088 | AB5: {=AA5+1} -> 46089 | AC5: {=AB5+1} -> 46090 | ... AH5: {=AG5+1} -> 46095 | AI5: 46096 | AJ5: {=AI5+1} -> 46097 | AK5: {=AJ5+1} -> 46098 | AL5: {=AK5+1} -> 46099 | AM5: {=AL5+1} -> 46100 | AN5: {=AM5+1} -> 46101 | AO5: {=AN5+1} -> 46102 | AP5: {=AO5+1} -> 46103 | AQ5: {=AP5+1} -> 46104 | ... AY5: {=AX5+1} -> 46112
U6: domingo | V6: segunda | W6: terça | X6: Quarta | Y6: Quinta | Z6: Sexta | AA6: Sabado | AB6: Domingo | AC6: segunda | AD6: terça | AE6: Quarta | AF6: Quinta | AG6: Sexta | AH6: Sabado | AI6: Domingo | AJ6: segunda | AK6: terça | AL6: Quarta | AM6: Quinta | AN6: Sexta | AO6: Sabado | AP6: Domingo | AQ6: segunda | AR6: terça | AS6: Quarta | AT6: Quinta | AU6: Sexta | AV6: Sabado | AW6: Domingo | AX6: Segunda | AY6: Terça
C7: Meta Total Mar/26 | D7: Meta 30/03 | E7: Realizado Mar/26 | F7: GAP Mar/26 | G7: Fechamento do GAP Total | H7: % da Meta | I7: Meta Total Mar/26 | J7: Meta 30/03 | K7: Realizado Mar/26 | L7: GAP Mar/26 | M7: Fechamento do GAP Total | O7: Meta | P7: Realizado | Q7: GAP | U7: {=CONCATENATE(U2," - ",U6)} -> 1 - domingo | V7: {=CONCATENATE(V2," - ",V6)} -> 2 - segunda | W7: {=CONCATENATE(W2," - ",W6)} -> 3 - terça | X7: {=CONCATENATE(X2," - ",X6)} -> 4 - Quarta | Y7: {=CONCATENATE(Y2," - ",Y6)} -> 5 - Quinta | Z7: {=CONCATENATE(Z2," - ",Z6)} -> 6 - Sexta | AA7: {=CONCATENATE(AA2," - ",AA6)} -> 7 - Sabado | AB7: {=CONCATENATE(AB2," - ",AB6)} -> 8 - Domingo | ... AY7: {=CONCATENATE(AY2," - ",AY6)} -> 31 - Terça
B8: Total | C8: {=SUM(C9:C16)} -> 1857781.8 | D8: {=SUM(D9:D16)} -> 1797853.4 | E8: {=SUM(E9:E16)} -> 1492282.6 | F8: {=SUM(F9:F16)} -> -365499.3 | G8: {=C8-E8} -> 365499.3 | H8: {=E8/C8} -> 0.80326038 | I8: {=SUM(I9:I16)} -> 20689.741 | J8: {=SUM(J9:J16)} -> 20022.33 | K8: {=SUM(K9:K16)} -> 17776 | L8: {=K8-I8} -> -2913.7407 | M8: {=I8-K8} -> 2913.7407 | O8: {=SUMPRODUCT(O9:O17,D9:D17)/D8} -> 95.506224 | P8: {=SUMPRODUCT(P9:P17,E9:E17)/E8} -> 100.73444 | Q8: {=P8-O8} -> 5.2282199 | S8: 1 | T8: Total Realizado | U8: 46426.11 | V8: 30935.49 | W8: 43473.53 | X8: 42587.27 | Y8: 42358.32 | Z8: 49202.11 | AA8: 56046.07 | AB8: 49789.3 | AC8: 32538.16 | AD8: 43699.93 | AE8: 41690 | AF8: 46329.08 | AG8: 62008.8 | AH8: 72757.96 | AI8: 53898.15 | AJ8: 38417 | AK8: 39221 | AL8: 51440 | AM8: 45234 | AN8: 58052 | AO8: 66982 | AP8: 55652 | AQ8: 37445.44 | AR8: 45686.91 | AS8: 44942 | AT8: 42992.51 | AU8: 49382.33 | AV8: 67237.37 | AW8: 51970.35 | AX8: 37778 | AY8: 47414.13
B9: Rio Mar Restaurante | C9: 900000 | D9: {=C9*30/31} -> 870967.74 | E9: {=954064.01-E10} -> 744324.25 | F9: {=E9-C9} -> -155675.75 | G9: {=C9-E9} -> 155675.75 | H9: {=E9/C9} -> 0.82702694 | I9: 9000 | J9: {=I9*30/31} -> 8709.6774 | K9: {=9612-K10} -> 6724 | L9: {=K9-I9} -> -2276 | M9: {=I9-K9} -> 2276 | O9: 100 | P9: {=E9/K9} -> 110.69665 | Q9: {=P9-O9} -> 10.696646 | S9: {=S8+1} -> 2 | T9: Rio Mar | U9: 30767.61 | V9: 26666.83 | W9: 30408.13 | X9: 30625 | Y9: 31085.68 | Z9: 25861.94 | AA9: 37316.81 | AB9: 27971.26 | AC9: 26817.41 | AD9: 29473.35 | AE9: 30667.45 | AF9: 34396.58 | AG9: 39670.35 | AH9: 45007.84 | AI9: 32449.79 | AJ9: 32285.78 | AK9: 30311.64 | AL9: 38897.5 | AM9: 29851.57 | AN9: 32593.31 | AO9: 32379.49 | AP9: 25788.27 | AQ9: 29131.29 | AR9: 29746.77 | AS9: 28802.02 | AT9: 27299.78 | AU9: 29767.85 | AV9: 31166.66 | AW9: 24375.08 | AX9: 21289 | AY9: 31191.72
B10: Rio Mar Mercado | C10: 225031.85 | D10: {=C10*30/31} -> 217772.76 | E10: {=155974.73+53765.03} -> 209739.76 | F10: {=E10-C10} -> -15292.087 | G10: {=C10-E10} -> 15292.087 | H10: {=E10/C10} -> 0.93204479 | I10: 3214.7407 | J10: {=I10*30/31} -> 3111.0394 | K10: 2888 | L10: {=K10-I10} -> -326.74068 | M10: {=I10-K10} -> 326.74068 | O10: 70 | P10: {=E10/K10} -> 72.624571 | Q10: {=P10-O10} -> 2.6245706 | S10: {=S9+1} -> 3 | T10: Paiva | U10: 11560.01 | V10: 0 | W10: 5441.87 | X10: 5012.11 | Y10: 5419.18 | Z10: 17059 | AA10: 14323.22 | AB10: 16709.1 | AC10: 0 | AD10: 6032.91 | AE10: 3653.53 | AF10: 4577.41 | AG10: 11764.74 | AH10: 16143.66 | AI10: 15979.61 | AJ10: 0 | AK10: 2687.73 | AL10: 5884.99 | AM10: 5980.66 | AN10: 8835.86 | AO10: 14871.69 | AP10: 15669.79 | AQ10: 0 | AR10: 5414.42 | AS10: 4829.04 | AT10: 5532.28 | AU10: 8690.87 | AV10: 22294.67 | AW10: 17889.85 | AX10: 0 | AY10: 6109.94
B11: Paiva | C11: 378000 | D11: {=C11*30/31} -> 365806.45 | E11: {=SUM(U10:AY10)} -> 258368.14 | F11: {=E11-C11} -> -119631.86 | G11: {=C11-E11} -> 119631.86 | H11: {=E11/C11} -> 0.6835136 | I11: 3150 | J11: {=I11*30/31} -> 3048.3871 | K11: 1730 | L11: {=K11-I11} -> -1420 | M11: {=I11-K11} -> 1420 | O11: 120 | P11: 149 | Q11: {=P11-O11} -> 29 | S11: {=S10+1} -> 4 | T11: Delivery | U11: 0 | V11: 0 | W11: 0 | X11: 0 | Y11: 0 | Z11: 0 | AA11: 0 | AB11: 0 | AC11: 0 | AD11: 0 | AE11: 0 | AF11: 0 | AG11: 0 | AH11: 527.99 | AI11: 213.78 | AJ11: 333.56 | AK11: 0 | AL11: 0 | AM11: 1043 | AN11: 3997 | AO11: 4362 | AP11: 5414 | AQ11: 3282.34 | AR11: 2961.2 | AS11: 2968.09 | AT11: 2913.87 | AU11: 3651.22 | AV11: 3429.2 | AW11: 5408.42 | AX11: 8865.96 | AY11: 3058 | AZ11: 0
B12: Delivery | C12: 150000 | D12: {=C12*30/31} -> 145161.29 | E12: {=SUM(U11:AY11)} -> 52429.63 | F12: {=E12-C12} -> -97570.37 | G12: {=C12-E12} -> 97570.37 | H12: {=E12/C12} -> 0.34953087 | I12: 1500 | J12: {=I12*30/31} -> 1451.6129 | K12: 590 | L12: {=K12-I12} -> -910 | M12: {=I12-K12} -> 910 | O12: 100 | P12: 90 | Q12: {=P12-O12} -> -10 | S12: {=S11+1} -> 5 | T12: Cabanga | U12: 1146.41 | V12: 1232.63 | W12: 1832.05 | X12: 1312.23 | Y12: 710.55 | Z12: 2302.62 | AA12: 897.43 | AB12: 1038 | AC12: 1722.77 | AD12: 1910.98 | AE12: 2194.63 | AF12: 2061.75 | AG12: 2388.89 | AH12: 7295.93 | AI12: 2247.92 | AJ12: 1166.02 | AK12: 1134.39 | AL12: 1187.61 | AM12: 1293.62 | AN12: 1786.18 | AO12: 2991.09 | AP12: 1668.17 | AQ12: 1276.64 | AR12: 1339.51 | AS12: 1224.63 | AT12: 1469.85 | AU12: 2244.54 | AV12: 5290.35 | AW12: 926.37 | AX12: 1025.4 | AY12: 1157.47
B13: Cabanga | C13: 56250 | D13: {=C13*30/31} -> 54435.484 | E13: {=SUM(U12:AY12)} -> 57476.63 | F13: {=E13-C13} -> 1226.63 | G13: {=C13-E13} -> -1226.63 | H13: {=E13/C13} -> 1.0218068 | I13: 1125 | J13: {=I13*30/31} -> 1088.7097 | K13: 1252 | L13: {=K13-I13} -> 127 | M13: {=I13-K13} -> -127 | O13: 50 | P13: 46 | Q13: {=P13-O13} -> -4 | S13: {=S12+1} -> 6 | T13: Velocity | U13: 1656.25 | V13: 1368.53 | W13: 1612.29 | X13: 1520.52 | Y13: 2241.76 | Z13: 1775.7 | AA13: 1724 | AB13: 2488.97 | AC13: 1773.84 | AD13: 2755.36 | AE13: 2135.46 | AF13: 2615.99 | AG13: 2785.2 | AH13: 1592.47 | AI13: 1398.7 | AJ13: 1741.79 | AK13: 2316.01 | AL13: 2297.93 | AM13: 3027.54 | AN13: 2380.11 | AO13: 1669.06 | AP13: 2190.49 | AQ13: 1721.09 | AR13: 2443.04 | AS13: 1678.77 | AT13: 1431.61 | AU13: 2795.84 | AV13: 1595.75 | AW13: 1506.79 | AX13: 3734.25 | AY13: 2123.46
B14: Velocity | C14: 52500 | D14: {=C14*30/31} -> 50806.452 | E14: {=SUM(U13:AY13)} -> 64098.57 | F14: {=E14-C14} -> 11598.57 | G14: {=C14-E14} -> -11598.57 | H14: {=E14/C14} -> 1.2209251 | I14: 1050 | J14: {=I14*30/31} -> 1016.129 | K14: 1432 | L14: {=K14-I14} -> 382 | M14: {=I14-K14} -> -382 | O14: 50 | P14: 45 | Q14: {=P14-O14} -> -5 | S14: {=S13+1} -> 7 | T14: Lagoa Azul | U14: 1295.83 | V14: 1271.77 | W14: 2418.81 | X14: 3162.67 | Y14: 2285.71 | Z14: 1654.18 | AA14: 1293.31 | AB14: 1581.97 | AC14: 2005.15 | AD14: 3042.02 | AE14: 1894.79 | AF14: 2016.57 | AG14: 1564.73 | AH14: 1672.08 | AI14: 1608.35 | AJ14: 2583.57 | AK14: 2257.9 | AL14: 2494.28 | AM14: 2927.28 | AN14: 7627.02 | AO14: 10327.39 | AP14: 4921.76 | AQ14: 1918.66 | AR14: 2741.66 | AS14: 3570.04 | AT14: 2961.79 | AU14: 1195.28 | AV14: 2077.55 | AW14: 1863.84 | AX14: 2519.29 | AY14: 2999.38
B15: Lagoa Azul | C15: 60000 | D15: {=C15*30/31} -> 58064.516 | E15: {=SUM(U14:AY14)} -> 83754.63 | F15: {=E15-C15} -> 23754.63 | G15: {=C15-E15} -> -23754.63 | H15: {=E15/C15} -> 1.3959105 | I15: 1200 | J15: {=I15*30/31} -> 1161.2903 | K15: 2840 | L15: {=K15-I15} -> 1640 | M15: {=I15-K15} -> -1640 | O15: 50 | P15: 29 | Q15: {=P15-O15} -> -21 | S15: {=S14+1} -> 8 | T15: Maison | U15: 0 | V15: 395.73 | W15: 1760.38 | X15: 954.74 | Y15: 615.44 | Z15: 548.38 | AA15: 491.3 | AB15: 0 | AC15: 218.99 | AD15: 485.31 | AE15: 1144.14 | AF15: 660.78 | AG15: 3328.04 | AH15: 517.99 | AI15: 0 | AJ15: 306.7 | AK15: 213.97 | AL15: 718.19 | AM15: 1109.72 | AN15: 832.01 | AO15: 472.38 | AP15: 0 | AQ15: 115.42 | AR15: 1040.31 | AS15: 1869.41 | AT15: 1383.33 | AU15: 1036.73 | AV15: 753.19 | AW15: 0 | AX15: 344.2 | AY15: 774.16
B16: Maison | C16: 36000 | D16: {=C16*30/31} -> 34838.71 | E16: {=SUM(U15:AY15)} -> 22090.94 | F16: {=E16-C16} -> -13909.06 | G16: {=C16-E16} -> 13909.06 | H16: {=E16/C16} -> 0.61363722 | I16: 450 | J16: {=I16*30/31} -> 435.48387 | K16: 320 | L16: {=K16-I16} -> -130 | M16: {=I16-K16} -> 130 | O16: 80 | P16: {=E16/K16} -> 69.034188 | Q16: {=P16-O16} -> -10.965813
B17: Média diária Total | C17: {=C8/31} -> 59928.447 | D17: {=D8/30} -> 59928.447 | E17: {=E8/31} -> 48138.147 | F17: {=F8/31} -> -11790.3 | G17: {=G8/(31-30)} -> 365499.3 | H17: {=E17/C17} -> 0.80326038 | I17: {=I8/31} -> 667.41099 | J17: {=I17*30/31} -> 645.8816 | K17: {=K8/30} -> 592.53333 | L17: {=L8/31} -> -93.991635 | M17: {=M8/(31-30)} -> 2913.7407 | S17: 1 | T17: Meta Total | U17: 59928.447 | V17: 59928.447 | W17: 59928.447 | X17: 59928.447 | Y17: 59928.447 | Z17: 59928.447 | AA17: 59928.447 | AB17: 59928.447 | AC17: 59928.447 | AD17: 59928.447 | AE17: 59928.447 | AF17: 59928.447 | AG17: 59928.447 | AH17: 59928.447 | AI17: 59928.447 | AJ17: 59928.447 | AK17: 59928.447 | AL17: 59928.447 | AM17: 59928.447 | AN17: 59928.447 | AO17: 59928.447 | AP17: 59928.447 | AQ17: 59928.447 | AR17: 59928.447 | AS17: 59928.447 | AT17: 59928.447 | AU17: 59928.447 | AV17: 59928.447 | AW17: 59928.447 | AX17: 59928.447 | AY17: 59928.447
S18: {=S17+1} -> 2 | T18: Meta Rio Mar | U18: 36291.35 | V18: {=U18} -> 36291.35 | W18: {=V18} -> 36291.35 | X18: {=W18} -> 36291.35 | Y18: {=X18} -> 36291.35 | Z18: {=Y18} -> 36291.35 | AA18: {=Z18} -> 36291.35 | AB18: {=AA18} -> 36291.35 | AC18: {=AB18} -> 36291.35 | ... AY18: {=AX18} -> 36291.35
S19: {=S18+1} -> 3 | T19: Meta Paiva | U19: 12193.548 | V19: {=U19} -> 12193.548 | W19: {=V19} -> 12193.548 | X19: {=W19} -> 12193.548 | Y19: {=X19} -> 12193.548 | Z19: {=Y19} -> 12193.548 | AA19: {=Z19} -> 12193.548 | AB19: {=AA19} -> 12193.548 | AC19: {=AB19} -> 12193.548 | ... AY19: {=AX19} -> 12193.548
S20: {=S19+1} -> 4 | T20: Meta Delivery | U20: 4838.7097 | V20: {=U20} -> 4838.7097 | W20: {=V20} -> 4838.7097 | X20: {=W20} -> 4838.7097 | Y20: {=X20} -> 4838.7097 | Z20: {=Y20} -> 4838.7097 | AA20: {=Z20} -> 4838.7097 | AB20: {=AA20} -> 4838.7097 | AC20: {=AB20} -> 4838.7097 | ... AY20: {=AX20} -> 4838.7097
S21: {=S20+1} -> 5 | T21: Meta Cabanga | U21: 1815 | V21: {=U21} -> 1815 | W21: {=V21} -> 1815 | X21: {=W21} -> 1815 | Y21: {=X21} -> 1815 | Z21: {=Y21} -> 1815 | AA21: {=Z21} -> 1815 | AB21: {=AA21} -> 1815 | AC21: {=AB21} -> 1815 | ... AY21: {=AX21} -> 1815
S22: {=S21+1} -> 6 | T22: Meta Velocity | U22: 1694 | V22: {=U22} -> 1694 | W22: {=V22} -> 1694 | X22: {=W22} -> 1694 | Y22: {=X22} -> 1694 | Z22: {=Y22} -> 1694 | AA22: {=Z22} -> 1694 | AB22: {=AA22} -> 1694 | AC22: {=AB22} -> 1694 | ... AY22: {=AX22} -> 1694
S23: {=S22+1} -> 7 | T23: Meta Lagoa Azul | U23: 1935 | V23: {=U23} -> 1935 | W23: {=V23} -> 1935 | X23: {=W23} -> 1935 | Y23: {=X23} -> 1935 | Z23: {=Y23} -> 1935 | AA23: {=Z23} -> 1935 | AB23: {=AA23} -> 1935 | AC23: {=AB23} -> 1935 | ... AY23: {=AX23} -> 1935
S24: {=S23+1} -> 8 | T24: Meta Maison | U24: 1161 | V24: {=U24} -> 1161 | W24: {=V24} -> 1161 | X24: {=W24} -> 1161 | Y24: {=X24} -> 1161 | Z24: {=Y24} -> 1161 | AA24: {=Z24} -> 1161 | AB24: {=AA24} -> 1161 | AC24: {=AB24} -> 1161 | ... AY24: {=AX24} -> 1161
S26: 1 | T26: Média Total | U26: {=AVERAGE(U8:AY8)} -> 48180.236 | V26: {=U26} -> 48180.236 | W26: {=V26} -> 48180.236 | X26: {=W26} -> 48180.236 | Y26: {=X26} -> 48180.236 | Z26: {=Y26} -> 48180.236 | AA26: {=Z26} -> 48180.236 | AB26: {=AA26} -> 48180.236 | AC26: {=AB26} -> 48180.236 | ... AY26: {=AX26} -> 48180.236
S27: {=S26+1} -> 2 | T27: Meta Rio Mar | U27: {=AVERAGE(U9:AY9)} -> 30776.25 | V27: {=U27} -> 30776.25 | W27: {=V27} -> 30776.25 | X27: {=W27} -> 30776.25 | Y27: {=X27} -> 30776.25 | Z27: {=Y27} -> 30776.25 | AA27: {=Z27} -> 30776.25 | AB27: {=AA27} -> 30776.25 | AC27: {=AB27} -> 30776.25 | ... AY27: {=AX27} -> 30776.25
S28: {=S27+1} -> 3 | T28: Média Paiva | U28: {=AVERAGE(U10:AY10)} -> 8334.4561 | V28: {=U28} -> 8334.4561 | W28: {=V28} -> 8334.4561 | X28: {=W28} -> 8334.4561 | Y28: {=X28} -> 8334.4561 | Z28: {=Y28} -> 8334.4561 | AA28: {=Z28} -> 8334.4561 | AB28: {=AA28} -> 8334.4561 | AC28: {=AB28} -> 8334.4561 | ... AY28: {=AX28} -> 8334.4561
S29: {=S28+1} -> 4 | T29: Média Delivery | U29: {=AVERAGE(U11:AY11)} -> 1691.2784 | V29: {=U29} -> 1691.2784 | W29: {=V29} -> 1691.2784 | X29: {=W29} -> 1691.2784 | Y29: {=X29} -> 1691.2784 | Z29: {=Y29} -> 1691.2784 | AA29: {=Z29} -> 1691.2784 | AB29: {=AA29} -> 1691.2784 | AC29: {=AB29} -> 1691.2784 | ... AY29: {=AX29} -> 1691.2784
S30: {=S29+1} -> 5 | T30: Média Cabanga | U30: {=AVERAGE(U12:AY12)} -> 1854.0848 | V30: {=U30} -> 1854.0848 | W30: {=V30} -> 1854.0848 | X30: {=W30} -> 1854.0848 | Y30: {=X30} -> 1854.0848 | Z30: {=Y30} -> 1854.0848 | AA30: {=Z30} -> 1854.0848 | AB30: {=AA30} -> 1854.0848 | AC30: {=AB30} -> 1854.0848 | ... AY30: {=AX30} -> 1854.0848
S31: {=S30+1} -> 6 | T31: Média Velocity | U31: {=AVERAGE(U13:AY13)} -> 2067.6958 | V31: {=U31} -> 2067.6958 | W31: {=V31} -> 2067.6958 | X31: {=W31} -> 2067.6958 | Y31: {=X31} -> 2067.6958 | Z31: {=Y31} -> 2067.6958 | AA31: {=Z31} -> 2067.6958 | AB31: {=AA31} -> 2067.6958 | AC31: {=AB31} -> 2067.6958 | ... AY31: {=AX31} -> 2067.6958
S32: {=S31+1} -> 7 | T32: Média Lagoa Azul | U32: {=AVERAGE(U14:AY14)} -> 2701.7623 | V32: {=U32} -> 2701.7623 | W32: {=V32} -> 2701.7623 | X32: {=W32} -> 2701.7623 | Y32: {=X32} -> 2701.7623 | Z32: {=Y32} -> 2701.7623 | AA32: {=Z32} -> 2701.7623 | AB32: {=AA32} -> 2701.7623 | AC32: {=AB32} -> 2701.7623 | ... AY32: {=AX32} -> 2701.7623
S33: {=S32+1} -> 8 | T33: Média Maison | U33: {=AVERAGE(U15:AY15)} -> 712.61097 | V33: {=U33} -> 712.61097 | W33: {=V33} -> 712.61097 | X33: {=W33} -> 712.61097 | Y33: {=X33} -> 712.61097 | Z33: {=Y33} -> 712.61097 | AA33: {=Z33} -> 712.61097 | AB33: {=AA33} -> 712.61097 | AC33: {=AB33} -> 712.61097 | ... AY33: {=AX33} -> 712.61097
T37: Média por Dia da Semana
T38: Total
T39: segunda | U39: terça | V39: Quarta | W39: Quinta | X39: Sexta | Y39: Sabado | Z39: Domingo
T40: {=_xlfn.AVERAGEIF($U$6:$AY$6,T39,$U$8:$AY$8)} -> 35422.818 | U40: {=_xlfn.AVERAGEIF($U$6:$AY$6,U39,$U$8:$AY$8)} -> 43899.1 | V40: {=_xlfn.AVERAGEIF($U$6:$AY$6,V39,$U$8:$AY$8)} -> 45164.817 | W40: {=_xlfn.AVERAGEIF($U$6:$AY$6,W39,$U$8:$AY$8)} -> 44228.478 | X40: {=_xlfn.AVERAGEIF($U$6:$AY$6,X39,$U$8:$AY$8)} -> 54661.31 | Y40: {=_xlfn.AVERAGEIF($U$6:$AY$6,Y39,$U$8:$AY$8)} -> 65755.85 | Z40: {=_xlfn.AVERAGEIF($U$6:$AY$6,Z39,$U$8:$AY$8)} -> 51547.182
T41: Rio Mar
D42: 46023 | E42: 46081 | F42: 46112 | G42: 46142 | H42: 46173 | I42: 46203 | J42: 46234 | K42: 46265 | L42: 46295 | M42: 46326 | O42: 46356 | P42: 46387 | T42: segunda | U42: terça | V42: Quarta | W42: Quinta | X42: Sexta | Y42: Sabado | Z42: Domingo
B43: META | D43: 1692201.4 | E43: 1502938.7 | F43: 1857781.8 | G43: 1926520.4 | H43: 2049259 | I43: 2171997.5 | J43: 2294736.1 | K43: 2417474.7 | L43: 2540213.2 | M43: 2716951.8 | O43: 2839690.3 | P43: 3124428.9 | T43: {=_xlfn.AVERAGEIF($U$6:$AY$6,T48,$U$9:$AY$9)} -> 27238.062 | U43: {=_xlfn.AVERAGEIF($U$6:$AY$6,U48,$U$9:$AY$9)} -> 30226.322 | V43: {=_xlfn.AVERAGEIF($U$6:$AY$6,V48,$U$9:$AY$9)} -> 32247.993 | W43: {=_xlfn.AVERAGEIF($U$6:$AY$6,W48,$U$9:$AY$9)} -> 30658.403 | X43: {=_xlfn.AVERAGEIF($U$6:$AY$6,X48,$U$9:$AY$9)} -> 31973.362 | Y43: {=_xlfn.AVERAGEIF($U$6:$AY$6,Y48,$U$9:$AY$9)} -> 36467.7 | Z43: {=_xlfn.AVERAGEIF($U$6:$AY$6,Z48,$U$9:$AY$9)} -> 28270.402
B44: META ACUMULADO | D44: {=D43} -> 1692201.4 | E44: {=D44+E43} -> 3195140.2 | F44: {=E44+F43} -> 5052922 | G44: {=F44+G43} -> 6979442.4 | H44: {=G44+H43} -> 9028701.4 | I44: {=H44+I43} -> 11200699 | J44: {=I44+J43} -> 13495435 | K44: {=J44+K43} -> 15912910 | L44: {=K44+L43} -> 18453123 | M44: {=L44+M43} -> 21170075 | O44: {=M44+O43} -> 24009765 | P44: {=O44+P43} -> 27134194 | T44: Paiva
T45: segunda | U45: terça | V45: Quarta | W45: Quinta | X45: Sexta | Y45: Sabado | Z45: Domingo
B46: REALIZADO | D46: 1692201.4 | E46: 1276895 | F46: {=E8} -> 1492282.6 | T46: {=_xlfn.AVERAGEIF($U$6:$AY$6,T39,$U$10:$AY$10)} -> 0 | U46: {=_xlfn.AVERAGEIF($U$6:$AY$6,U39,$U$10:$AY$10)} -> 5137.374 | V46: {=_xlfn.AVERAGEIF($U$6:$AY$6,V39,$U$10:$AY$10)} -> 4844.9175 | W46: {=_xlfn.AVERAGEIF($U$6:$AY$6,W39,$U$10:$AY$10)} -> 5377.3825 | X46: {=_xlfn.AVERAGEIF($U$6:$AY$6,X39,$U$10:$AY$10)} -> 11587.618 | Y46: {=_xlfn.AVERAGEIF($U$6:$AY$6,Y39,$U$10:$AY$10)} -> 16908.31 | Z46: {=_xlfn.AVERAGEIF($U$6:$AY$6,Z39,$U$10:$AY$10)} -> 15561.672
...

Sheet Acompanhamento Abr26
W2: 1 | X2: {=W2+1} -> 2 | Y2: {=X2+1} -> 3 | Z2: {=Y2+1} -> 4 | AA2: {=Z2+1} -> 5 | AB2: {=AA2+1} -> 6 | AC2: {=AB2+1} -> 7 | AD2: {=AC2+1} -> 8 | AE2: {=AD2+1} -> 9 | ... AZ2: {=AY2+1} -> 30
C3: TABELA DE META
W4: {=WEEKDAY(W5)} -> 4 | X4: {=WEEKDAY(X5)} -> 5 | Y4: {=WEEKDAY(Y5)} -> 6 | Z4: {=WEEKDAY(Z5)} -> 7 | AA4: {=WEEKDAY(AA5)} -> 1 | AB4: {=WEEKDAY(AB5)} -> 2 | AC4: {=WEEKDAY(AC5)} -> 3 | AD4: {=WEEKDAY(AD5)} -> 4 | ... AZ4: {=WEEKDAY(AZ5)} -> 5
C5: 1. FATURAMENTO | E5: Fechamento | F5: 30 | W5: 46113 | X5: {=W5+1} -> 46114 | Y5: {=X5+1} -> 46115 | Z5: {=Y5+1} -> 46116 | AA5: {=Z5+1} -> 46117 | AB5: {=AA5+1} -> 46118 | AC5: {=AB5+1} -> 46119 | AD5: {=AC5+1} -> 46120 | AE5: {=AD5+1} -> 46121 | ... AZ5: {=AY5+1} -> 46142
W6: {=VLOOKUP(W4,'References'!$C$8:$E$15,3,0)} -> Quarta | X6: {=VLOOKUP(X4,'References'!$C$8:$E$15,3,0)} -> Quinta | Y6: {=VLOOKUP(Y4,'References'!$C$8:$E$15,3,0)} -> Sexta | Z6: {=VLOOKUP(Z4,'References'!$C$8:$E$15,3,0)} -> Sábado | AA6: {=VLOOKUP(AA4,'References'!$C$8:$E$15,3,0)} -> Domingo | AB6: {=VLOOKUP(AB4,'References'!$C$8:$E$15,3,0)} -> Segunda | AC6: {=VLOOKUP(AC4,'References'!$C$8:$E$15,3,0)} -> Terça | AD6: {=VLOOKUP(AD4,'References'!$C$8:$E$15,3,0)} -> Quarta | ... AZ6: {=VLOOKUP(AZ4,'References'!$C$8:$E$15,3,0)} -> Quinta
D7: Líder | E7: Meta Total | F7: Meta Parcial | G7: Realizado | H7: GAP | I7: Média | J7: Média | K7: Média | L7: % da Meta | V7: FATURAMENTO | W7: {=CONCATENATE(W2," - ",W6)} -> 1 - Quarta | X7: {=CONCATENATE(X2," - ",X6)} -> 2 - Quinta | Y7: {=CONCATENATE(Y2," - ",Y6)} -> 3 - Sexta | Z7: {=CONCATENATE(Z2," - ",Z6)} -> 4 - Sábado | AA7: {=CONCATENATE(AA2," - ",AA6)} -> 5 - Domingo | AB7: {=CONCATENATE(AB2," - ",AB6)} -> 6 - Segunda | AC7: {=CONCATENATE(AC2," - ",AC6)} -> 7 - Terça | AD7: {=CONCATENATE(AD2," - ",AD6)} -> 8 - Quarta | ... AZ7: {=CONCATENATE(AZ2," - ",AZ6)} -> 30 - Quinta
D8: Responsável | E8: 46142 | F8: 46140 | G8: 46140 | H8: 46140 | I8: Meta | J8: 46140 | K8: Recalibrada | L8: Atingido | U8: 1 | V8: Total Realizado | W8: {=SUM(W9:W16)} -> 46249.24 | X8: {=SUM(X9:X16)} -> 59336.38 | Y8: {=SUM(Y9:Y16)} -> 41431.94 | Z8: {=SUM(Z9:Z16)} -> 45542.36 | AA8: {=SUM(AA9:AA16)} -> 29935.73 | AB8: {=SUM(AB9:AB16)} -> 31504.56 | AC8: {=SUM(AC9:AC16)} -> 37869.3 | AD8: {=SUM(AD9:AD16)} -> 54374.5 | ... AZ8: {=SUM(AZ9:AZ16)} -> 64093.81
B9: 1 | C9: Rio Mar Restaurante | D9: Arthur | E9: 660000 | F9: {=E9*$F$5/30} -> 660000 | G9: {=SUM(W9:AZ9)} -> 621310.69 | H9: {=G9-F9} -> -38689.31 | I9: {=F9/$F$5} -> 22000 | J9: {=G9/$F$5} -> 20710.356 | K9: {=(E9-H9-F9)/(30-$F$5)} | L9: {=G9/F9} -> 0.94137983 | U9: {=U8+1} -> 2 | V9: {=C9} -> Rio Mar Restaurante | W9: {=24941.76} -> 24941.76 | X9: 22589.04 | Y9: 12247.25 | Z9: {=16542.61} -> 16542.61 | AA9: 10429.57 | AB9: 17627.03 | AC9: {=17414.54} -> 17414.54 | AD9: 20132.27 | AE9: 23363.98 | AF9: 23120.55 | AG9: 27086.8 | AH9: 20761.85 | AI9: 21339.86 | AJ9: 11268.29 | AK9: 22148.3 | AL9: 22825.09 | AM9: 21482.95 | AN9: 20951.99 | AO9: 18878.68 | AP9: 22427.21 | AQ9: 20862.75 | AR9: 21892.45 | AS9: 20354.6 | AT9: {=25109.32} -> 25109.32 | AU9: 26231.64 | AV9: 20828.07 | AW9: 15892.58 | AX9: 19205.96 | AY9: 26236.33 | AZ9: 27117.37
B10: {=B9+1} -> 2 | C10: Rio Mar Mercado | D10: Cleverton | E10: 240033.97 | F10: {=E10*$F$5/30} -> 240033.97 | G10: {=SUM(W10:AZ10)} -> 194442.15 | H10: {=G10-F10} -> -45591.82 | I10: {=F10/$F$5} -> 8001.1323 | J10: {=G10/$F$5} -> 6481.405 | K10: {=(E10-H10-F10)/(30-$F$5)} | L10: {=G10/F10} -> 0.81006097 | U10: {=U9+1} -> 3 | V10: {=C10} -> Rio Mar Mercado | W10: {=1029.09+5706.76} -> 6735.85 | X10: {=6882.21+1206.07} -> 8088.28 | Y10: {=3805.46+900.59} -> 4706.05 | Z10: {=989.98+4171.08} -> 5161.06 | AA10: {=3183.59+551.83} -> 3735.42 | AB10: {=4115.17+210.6} -> 4325.77 | AC10: {=3683.12+1707.41} -> 5390.53 | AD10: {=4781.84+1203.48} -> 5985.32 | AE10: {=5892.23+436.34} -> 6328.57 | AF10: {=5284.87+2553.37} -> 7838.24 | AG10: {=6084.8+1269.95} -> 7354.75 | AH10: {=4007.09+1245.88} -> 5252.97 | AI10: {=3737.84+1892.8} -> 5630.64 | AJ10: {=2514.95+532.37} -> 3047.32 | AK10: {=6094.38+3364.22} -> 9458.6 | AL10: {=5507.39+2772.92} -> 8280.31 | AM10: {=6774.88+1829.82} -> 8604.7 | AN10: {=7004.61+3219.99} -> 10224.6 | AO10: {=4572.04+273.24} -> 4845.28 | AP10: {=4457.39+1100.87} -> 5558.26 | AQ10: {=4903.26+532.23} -> 5435.49 | AR10: {=3635.23+718.91} -> 4354.14 | AS10: {=5600.96+2052.87} -> 7653.83 | AT10: {=3972.7+3970.31} -> 7943.01 | AU10: {=5451.81+1312.84} -> 6764.65 | AV10: {=7629.45+1400.9} -> 9030.35 | AW10: {=4640.34+756.33} -> 5396.67 | AX10: {=5703.15+988.31} -> 6691.46 | AY10: {=5687.46+1862.36} -> 7549.82 | AZ10: {=4929.87+2140.34} -> 7070.21
B11: {=B10+1} -> 3 | C11: Paiva | D11: Gleibson | E11: 300195 | F11: {=E11*$F$5/30} -> 300195 | G11: {=SUM(W11:AZ11)} -> 292791.48 | H11: {=G11-F11} -> -7403.522 | I11: {=F11/$F$5} -> 10006.5 | J11: {=G11/$F$5} -> 9759.7159 | K11: {=(E11-H11-F11)/(30-$F$5)} | L11: {=G11/F11} -> 0.97533762 | U11: {=U10+1} -> 4 | V11: Paiva | W11: 5331.94 | X11: 11550.55 | Y11: 17715.49 | Z11: 18550.48 | AA11: 9044.41 | AB11: 0 | AC11: 7140.01 | AD11: 3595.22 | AE11: 5899.78 | AF11: 10569.98 | AG11: 16440.48 | AH11: 7950.44 | AI11: 0 | AJ11: 3955.29 | AK11: 4132.01 | AL11: 5207.45 | AM11: 8576.51 | AN11: 16063.18 | AO11: 19437.95 | AP11: {=11907.88} -> 11907.88 | AQ11: 23582.198 | AR11: 7576.42 | AS11: {=6699.74} -> 6699.74 | AT11: 11584.51 | AU11: {=19737.52} -> 19737.52 | AV11: 17809.2 | AW11: 0 | AX11: 7661.37 | AY11: 5845.57 | AZ11: 9225.9 | BA11: 0
B12: {=B11+1} -> 4 | C12: Delivery | D12: Aline | E12: 157500 | F12: {=E12*$F$5/30} -> 157500 | G12: {=SUM(W12:AZ12)} -> 227230.36 | H12: {=G12-F12} -> 69730.36 | I12: {=F12/$F$5} -> 5250 | J12: {=G12/$F$5} -> 7574.3453 | K12: {=(E12-H12-F12)/(30-$F$5)} | L12: {=G12/F12} -> 1.4427324 | U12: {=U11+1} -> 5 | V12: Delivery | W12: 2525.51 | X12: 11503.37 | Y12: 3903.69 | Z12: 2800.03 | AA12: 4554.73 | AB12: 4640.86 | AC12: 3759.31 | AD12: 17766.1 | AE12: 3065.3 | AF12: 5618 | AG12: 7730.81 | AH12: 6963.99 | AI12: {=8033.34} -> 8033.34 | AJ12: 6564.29 | AK12: 5410.48 | AL12: 4918.36 | AM12: 5821 | AN12: 7181.86 | AO12: 8118.95 | AP12: 6817.44 | AQ12: 9921.59 | AR12: 6685.67 | AS12: 21174.48 | AT12: 6893.31 | AU12: 8016.41 | AV12: 11431.51 | AW12: 8865.96 | AX12: 6324.6 | AY12: 7368.11 | AZ12: 12851.3
B13: {=B12+1} -> 5 | C13: Cabanga | D13: Cleverton | E13: 74999.999 | F13: {=E13*$F$5/30} -> 74999.999 | G13: {=SUM(W13:AZ13)} -> 34351.75 | H13: {=G13-F13} -> -40648.249 | I13: {=F13/$F$5} -> 2500 | J13: {=G13/$F$5} -> 1145.0583 | K13: {=(E13-H13-F13)/(30-$F$5)} | L13: {=G13/F13} -> 0.45802334 | U13: {=U12+1} -> 6 | V13: Cabanga | W13: 1106.87 | X13: 804.79 | Y13: 210.6 | Z13: 473.85 | AA13: 158.88 | AB13: 832.49 | AC13: 101.28 | AD13: 1342.06 | AE13: 1309.44 | AF13: 1800.34 | AG13: 3089.33 | AH13: 568.13 | AI13: 1324.74 | AJ13: 1231.24 | AK13: 1059.68 | AL13: 832.44 | AM13: 1556.22 | AN13: 1402.02 | AO13: 1286.94 | AP13: 1501.49 | AQ13: 1775.55 | AR13: 926.45 | AS13: 969.74 | AT13: 986.01 | AU13: 2160.07 | AV13: 1847.37 | AW13: 1025.4 | AX13: 649.87 | AY13: 999.53 | AZ13: 1018.93
B14: {=B13+1} -> 6 | C14: Velocity | D14: Cleverton | E14: 74999.992 | F14: {=E14*$F$5/30} -> 74999.992 | G14: {=SUM(W14:AZ14)} -> 49354.33 | H14: {=G14-F14} -> -25645.662 | I14: {=F14/$F$5} -> 2499.9997 | J14: {=G14/$F$5} -> 1645.1443 | K14: {=(E14-H14-F14)/(30-$F$5)} | L14: {=G14/F14} -> 0.6580578 | U14: {=U13+1} -> 7 | V14: Velocity | W14: 1033.05 | X14: 1786.32 | Y14: 1912.9 | Z14: 1089.3 | AA14: 907.54 | AB14: 1860.49 | AC14: 1515.56 | AD14: 1833.34 | AE14: 1951.18 | AF14: 1855.16 | AG14: 1201.74 | AH14: 963.7 | AI14: 1600.07 | AJ14: 2543 | AK14: 1934.18 | AL14: 1883.13 | AM14: 1884.05 | AN14: 1036.65 | AO14: 1069.6 | AP14: 1103.92 | AQ14: 1116.38 | AR14: 1273.6 | AS14: 1983.07 | AT14: 2646.98 | AU14: 1158.3 | AV14: 1037.47 | AW14: 3734.25 | AX14: 1790.6 | AY14: 1625.74 | AZ14: 2023.06
B15: {=B14+1} -> 7 | C15: Lagoa Azul | D15: Cleverton | E15: 75000 | F15: {=E15*$F$5/30} -> 75000 | G15: {=SUM(W15:AZ15)} -> 61945.36 | H15: {=G15-F15} -> -13054.64 | I15: {=F15/$F$5} -> 2500 | J15: {=G15/$F$5} -> 2064.8453 | K15: {=(E15-H15-F15)/(30-$F$5)} | L15: {=G15/F15} -> 0.82593814 | U15: {=U14+1} -> 8 | V15: Lagoa Azul | W15: 2652.62 | X15: 1289.92 | Y15: 735.96 | Z15: 925.03 | AA15: 1105.18 | AB15: 1971.53 | AC15: 2004.19 | AD15: 2384.61 | AE15: 3321.36 | AF15: 2284.76 | AG15: 1815.81 | AH15: 1693.39 | AI15: 1049.64 | AJ15: 2815.65 | AK15: 2684.94 | AL15: 2783.99 | AM15: 2001.18 | AN15: 1599.2 | AO15: 828.95 | AP15: 1921.52 | AQ15: 1840.47 | AR15: 2236.52 | AS15: 2788.97 | AT15: 1761.79 | AU15: 3000.95 | AV15: 1436.71 | AW15: 2519.29 | AX15: 3051.91 | AY15: 2938.52 | AZ15: 2500.8
B16: {=B15+1} -> 8 | C16: Maison | D16: Duda | E16: 59400 | F16: {=E16*$F$5/30} -> 59400 | G16: {=SUM(W16:AZ16)} -> 25829.52 | H16: {=G16-F16} -> -33570.48 | I16: {=F16/$F$5} -> 1980 | J16: {=G16/$F$5} -> 860.984 | K16: {=(E16-H16-F16)/(30-$F$5)} | L16: {=G16/F16} -> 0.4348404 | U16: {=U15+1} -> 9 | V16: Maison | W16: 1921.64 | X16: 1724.11 | Y16: 0 | Z16: 0 | AA16: 0 | AB16: 246.39 | AC16: 543.88 | AD16: 1335.58 | AE16: 872.47 | AF16: 1119.79 | AG16: 775.83 | AH16: 0 | AI16: 78.74 | AJ16: 1037.47 | AK16: 867.96 | AL16: 1172.41 | AM16: 1362.95 | AN16: 689.52 | AO16: 0 | AP16: 701.02 | AQ16: 0 | AR16: 568.25 | AS16: 3529.76 | AT16: 908.17 | AU16: 940.83 | AV16: 0 | AW16: 344.2 | AX16: 1697.3 | AY16: 1105.01 | AZ16: 2286.24
D17: Total | E17: {=SUM(E9:E16)} -> 1642129 | F17: {=SUM(F9:F16)} -> 1642129 | G17: {=SUM(G9:G16)} -> 1507255.6 | H17: {=SUM(H9:H16)} -> -134873.32 | I17: {=F17/$F$5} -> 54737.632 | J17: {=G17/$F$5} -> 50241.855 | K17: {=(E17-H17-F17)/(30-$F$5)} | L17: {=G17/F17} -> 0.91786679
U18: 1 | V18: Total Meta | W18: {=SUM(W19:W26)} -> 54737.632 | X18: {=SUM(X19:X26)} -> 54737.632 | Y18: {=SUM(Y19:Y26)} -> 54737.632 | Z18: {=SUM(Z19:Z26)} -> 54737.632 | AA18: {=SUM(AA19:AA26)} -> 54737.632 | AB18: {=SUM(AB19:AB26)} -> 54737.632 | AC18: {=SUM(AC19:AC26)} -> 54737.632 | AD18: {=SUM(AD19:AD26)} -> 54737.632 | ... AZ18: {=SUM(AZ19:AZ26)} -> 54737.632
C19: 2. PEDIDOS | U19: {=U18+1} -> 2 | V19: {=V9} -> Rio Mar Restaurante | W19: {=I9} -> 22000 | X19: {=W19} -> 22000 | Y19: {=X19} -> 22000 | Z19: {=Y19} -> 22000 | AA19: {=Z19} -> 22000 | AB19: {=AA19} -> 22000 | AC19: {=AB19} -> 22000 | AD19: {=AC19} -> 22000 | AE19: {=AD19} -> 22000 | ... AZ19: {=AY19} -> 22000
U20: {=U19+1} -> 3 | V20: {=V10} -> Rio Mar Mercado | W20: {=I10} -> 8001.1323 | X20: {=W20} -> 8001.1323 | Y20: {=X20} -> 8001.1323 | Z20: {=Y20} -> 8001.1323 | AA20: {=Z20} -> 8001.1323 | AB20: {=AA20} -> 8001.1323 | AC20: {=AB20} -> 8001.1323 | AD20: {=AC20} -> 8001.1323 | AE20: {=AD20} -> 8001.1323 | ... AZ20: {=AY20} -> 8001.1323
D21: Líder | E21: Meta Total | F21: Meta Parcial | G21: Realizado | H21: GAP | I21: Média | J21: Média | K21: Média | L21: % da Meta | U21: {=U20+1} -> 4 | V21: {=V11} -> Paiva | W21: {=I11} -> 10006.5 | X21: {=W21} -> 10006.5 | Y21: {=X21} -> 10006.5 | Z21: {=Y21} -> 10006.5 | AA21: {=Z21} -> 10006.5 | AB21: {=AA21} -> 10006.5 | AC21: {=AB21} -> 10006.5 | AD21: {=AC21} -> 10006.5 | AE21: {=AD21} -> 10006.5 | ... AZ21: {=AY21} -> 10006.5
D22: Responsável | E22: {=E8} -> 46142 | F22: {=F8} -> 46140 | G22: {=G8} -> 46140 | H22: {=H8} -> 46140 | I22: {=I8} -> Meta | J22: {=J8} -> 46140 | K22: {=K8} -> Recalibrada | L22: {=L8} -> Atingido | U22: {=U21+1} -> 5 | V22: {=V12} -> Delivery | W22: {=I12} -> 5250 | X22: {=W22} -> 5250 | Y22: {=X22} -> 5250 | Z22: {=Y22} -> 5250 | AA22: {=Z22} -> 5250 | AB22: {=AA22} -> 5250 | AC22: {=AB22} -> 5250 | AD22: {=AC22} -> 5250 | AE22: {=AD22} -> 5250 | ... AZ22: {=AY22} -> 5250
B23: 1 | C23: Rio Mar Restaurante | D23: Arthur | E23: 6000 | F23: {=E23*$F$5/30} -> 6000 | G23: 5089 | H23: {=G23-F23} -> -911 | I23: {=F23/$F$5} -> 200 | J23: {=G23/$F$5} -> 169.63333 | K23: {=(E23-H23-F23)/(30-$F$5)} | L23: {=G23/F23} -> 0.84816667 | U23: {=U22+1} -> 6 | V23: {=V13} -> Cabanga | W23: {=I13} -> 2500 | X23: {=W23} -> 2500 | Y23: {=X23} -> 2500 | Z23: {=Y23} -> 2500 | AA23: {=Z23} -> 2500 | AB23: {=AA23} -> 2500 | AC23: {=AB23} -> 2500 | AD23: {=AC23} -> 2500 | AE23: {=AD23} -> 2500 | ... AZ23: {=AY23} -> 2500
B24: {=B23+1} -> 2 | C24: Rio Mar Mercado | D24: Cleverton | E24: 3429.0567 | F24: {=E24*$F$5/30} -> 3429.0567 | G24: {=1775+471} -> 2246 | H24: {=G24-F24} -> -1183.0567 | I24: {=F24/$F$5} -> 114.30189 | J24: {=G24/$F$5} -> 74.866667 | K24: {=(E24-H24-F24)/(30-$F$5)} | L24: {=G24/F24} -> 0.65499062 | U24: {=U23+1} -> 7 | V24: {=V14} -> Velocity | W24: {=I14} -> 2499.9997 | X24: {=W24} -> 2499.9997 | Y24: {=X24} -> 2499.9997 | Z24: {=Y24} -> 2499.9997 | AA24: {=Z24} -> 2499.9997 | AB24: {=AA24} -> 2499.9997 | AC24: {=AB24} -> 2499.9997 | AD24: {=AC24} -> 2499.9997 | AE24: {=AD24} -> 2499.9997 | ... AZ24: {=AY24} -> 2499.9997
B25: {=B24+1} -> 3 | C25: Paiva | D25: Gleibson | E25: 2144.25 | F25: {=E25*$F$5/30} -> 2144.25 | G25: 1806 | H25: {=G25-F25} -> -338.25 | I25: {=F25/$F$5} -> 71.475 | J25: {=G25/$F$5} -> 60.2 | K25: {=(E25-H25-F25)/(30-$F$5)} | L25: {=G25/F25} -> 0.84225254 | U25: {=U24+1} -> 8 | V25: {=V15} -> Lagoa Azul | W25: {=I15} -> 2500 | X25: {=W25} -> 2500 | Y25: {=X25} -> 2500 | Z25: {=Y25} -> 2500 | AA25: {=Z25} -> 2500 | AB25: {=AA25} -> 2500 | AC25: {=AB25} -> 2500 | AD25: {=AC25} -> 2500 | AE25: {=AD25} -> 2500 | ... AZ25: {=AY25} -> 2500
B26: {=B25+1} -> 4 | C26: Delivery | D26: Aline | E26: 2250 | F26: {=E26*$F$5/30} -> 2250 | G26: 2124 | H26: {=G26-F26} -> -126 | I26: {=F26/$F$5} -> 75 | J26: {=G26/$F$5} -> 70.8 | K26: {=(E26-H26-F26)/(30-$F$5)} | L26: {=G26/F26} -> 0.944 | U26: {=U25+1} -> 9 | V26: {=V16} -> Maison | W26: {=I16} -> 1980 | X26: {=W26} -> 1980 | Y26: {=X26} -> 1980 | Z26: {=Y26} -> 1980 | AA26: {=Z26} -> 1980 | AB26: {=AA26} -> 1980 | AC26: {=AB26} -> 1980 | AD26: {=AC26} -> 1980 | AE26: {=AD26} -> 1980 | ... AZ26: {=AY26} -> 1980
B27: {=B26+1} -> 5 | C27: Cabanga | D27: Cleverton | E27: 1499.9998 | F27: {=E27*$F$5/30} -> 1499.9998 | G27: 727 | H27: {=G27-F27} -> -772.99985 | I27: {=F27/$F$5} -> 49.999995 | J27: {=G27/$F$5} -> 24.233333 | K27: {=(E27-H27-F27)/(30-$F$5)} | L27: {=G27/F27} -> 0.48466672
B28: {=B27+1} -> 6 | C28: Velocity | D28: Cleverton | E28: 2500 | F28: {=E28*$F$5/30} -> 2500 | G28: 1051 | H28: {=G28-F28} -> -1449 | I28: {=F28/$F$5} -> 83.333332 | J28: {=G28/$F$5} -> 35.033333 | K28: {=(E28-H28-F28)/(30-$F$5)} | L28: {=G28/F28} -> 0.4204 | U28: 1 | V28: Média | W28: {=AVERAGE(W8:AZ8)} -> 50241.855 | X28: {=W28} -> 50241.855 | Y28: {=X28} -> 50241.855 | Z28: {=Y28} -> 50241.855 | AA28: {=Z28} -> 50241.855 | AB28: {=AA28} -> 50241.855 | AC28: {=AB28} -> 50241.855 | AD28: {=AC28} -> 50241.855 | AE28: {=AD28} -> 50241.855 | ... AZ28: {=AY28} -> 50241.855
B29: {=B28+1} -> 7 | C29: Lagoa Azul | D29: Cleverton | E29: 1875 | F29: {=E29*$F$5/30} -> 1875 | G29: 2120 | H29: {=G29-F29} -> 245.00001 | I29: {=F29/$F$5} -> 62.5 | J29: {=G29/$F$5} -> 70.666667 | K29: {=(E29-H29-F29)/(30-$F$5)} | L29: {=G29/F29} -> 1.1306667 | U29: {=U28+1} -> 2 | V29: {=V19} -> Rio Mar Restaurante | W29: {=AVERAGE(W9:AZ9)} -> 20710.356 | X29: {=W29} -> 20710.356 | Y29: {=X29} -> 20710.356 | Z29: {=Y29} -> 20710.356 | AA29: {=Z29} -> 20710.356 | AB29: {=AA29} -> 20710.356 | AC29: {=AB29} -> 20710.356 | AD29: {=AC29} -> 20710.356 | AE29: {=AD29} -> 20710.356 | ... AZ29: {=AY29} -> 20710.356
B30: {=B29+1} -> 8 | C30: Maison | D30: Duda | E30: 495 | F30: {=E30*$F$5/30} -> 495 | G30: 341 | H30: {=G30-F30} -> -154 | I30: {=F30/$F$5} -> 16.5 | J30: {=G30/$F$5} -> 11.366667 | K30: {=(E30-H30-F30)/(30-$F$5)} | L30: {=G30/F30} -> 0.68888889 | U30: {=U29+1} -> 3 | V30: {=V20} -> Rio Mar Mercado | W30: {=AVERAGE(W10:AZ10)} -> 6481.405 | X30: {=W30} -> 6481.405 | Y30: {=X30} -> 6481.405 | Z30: {=Y30} -> 6481.405 | AA30: {=Z30} -> 6481.405 | AB30: {=AA30} -> 6481.405 | AC30: {=AB30} -> 6481.405 | AD30: {=AC30} -> 6481.405 | AE30: {=AD30} -> 6481.405 | ... AZ30: {=AY30} -> 6481.405
D31: Total | E31: {=SUM(E23:E30)} -> 20193.307 | F31: {=SUM(F23:F30)} -> 20193.307 | G31: {=SUM(G23:G30)} -> 15504 | H31: {=SUM(H23:H30)} -> -4689.3065 | I31: {=F31/$F$5} -> 673.11022 | J31: {=G31/$F$5} -> 516.8 | K31: {=(E31-H31-F31)/(30-$F$5)} | L31: {=G31/F31} -> 0.76777916 | U31: {=U30+1} -> 4 | V31: {=V21} -> Paiva | W31: {=AVERAGE(W11:AZ11)} -> 9759.7159 | X31: {=W31} -> 9759.7159 | Y31: {=X31} -> 9759.7159 | Z31: {=Y31} -> 9759.7159 | AA31: {=Z31} -> 9759.7159 | AB31: {=AA31} -> 9759.7159 | AC31: {=AB31} -> 9759.7159 | AD31: {=AC31} -> 9759.7159 | AE31: {=AD31} -> 9759.7159 | ... AZ31: {=AY31} -> 9759.7159
U32: {=U31+1} -> 5 | V32: {=V22} -> Delivery | W32: {=AVERAGE(W12:AZ12)} -> 7574.3453 | X32: {=W32} -> 7574.3453 | Y32: {=X32} -> 7574.3453 | Z32: {=Y32} -> 7574.3453 | AA32: {=Z32} -> 7574.3453 | AB32: {=AA32} -> 7574.3453 | AC32: {=AB32} -> 7574.3453 | AD32: {=AC32} -> 7574.3453 | AE32: {=AD32} -> 7574.3453 | ... AZ32: {=AY32} -> 7574.3453
U33: {=U32+1} -> 6 | V33: {=V23} -> Cabanga | W33: {=AVERAGE(W13:AZ13)} -> 1145.0583 | X33: {=W33} -> 1145.0583 | Y33: {=X33} -> 1145.0583 | Z33: {=Y33} -> 1145.0583 | AA33: {=Z33} -> 1145.0583 | AB33: {=AA33} -> 1145.0583 | AC33: {=AB33} -> 1145.0583 | AD33: {=AC33} -> 1145.0583 | AE33: {=AD33} -> 1145.0583 | ... AZ33: {=AY33} -> 1145.0583
C34: 3. TICKET MÉDIO | U34: {=U33+1} -> 7 | V34: {=V24} -> Velocity | W34: {=AVERAGE(W14:AZ14)} -> 1645.1443 | X34: {=W34} -> 1645.1443 | Y34: {=X34} -> 1645.1443 | Z34: {=Y34} -> 1645.1443 | AA34: {=Z34} -> 1645.1443 | AB34: {=AA34} -> 1645.1443 | AC34: {=AB34} -> 1645.1443 | AD34: {=AC34} -> 1645.1443 | AE34: {=AD34} -> 1645.1443 | ... AZ34: {=AY34} -> 1645.1443
D35: Meta | E35: Realizado | F35: GAP | U35: {=U34+1} -> 8 | V35: {=V25} -> Lagoa Azul | W35: {=AVERAGE(W15:AZ15)} -> 2064.8453 | X35: {=W35} -> 2064.8453 | Y35: {=X35} -> 2064.8453 | Z35: {=Y35} -> 2064.8453 | AA35: {=Z35} -> 2064.8453 | AB35: {=AA35} -> 2064.8453 | AC35: {=AB35} -> 2064.8453 | AD35: {=AC35} -> 2064.8453 | AE35: {=AD35} -> 2064.8453 | ... AZ35: {=AY35} -> 2064.8453
B36: 1 | C36: Rio Mar Restaurante | D36: 100 | E36: {=G9/G23} -> 122.08895 | F36: {=E36-D36} -> 22.088955 | U36: {=U35+1} -> 9 | V36: {=V26} -> Maison | W36: {=AVERAGE(W16:AZ16)} -> 860.984 | X36: {=W36} -> 860.984 | Y36: {=X36} -> 860.984 | Z36: {=Y36} -> 860.984 | AA36: {=Z36} -> 860.984 | AB36: {=AA36} -> 860.984 | AC36: {=AB36} -> 860.984 | AD36: {=AC36} -> 860.984 | AE36: {=AD36} -> 860.984 | ... AZ36: {=AY36} -> 860.984
B37: {=B36+1} -> 2 | C37: Rio Mar Mercado | D37: 70 | E37: {=G10/G24} -> 86.57264 | F37: {=E37-D37} -> 16.57264
B38: {=B37+1} -> 3 | C38: Paiva | D38: 120 | E38: {=G11/G25} -> 162.12153 | F38: {=E38-D38} -> 42.121527 | V38: PEDIDOS
B39: {=B38+1} -> 4 | C39: Delivery | D39: 70 | E39: {=G12/G26} -> 106.98228 | F39: {=E39-D39} -> 36.982279 | U39: 1 | V39: Total Realizado
B40: {=B39+1} -> 5 | C40: Cabanga | D40: 50 | E40: {=G13/G27} -> 47.251376 | F40: {=E40-D40} -> -2.7486245 | U40: {=U39+1} -> 2 | V40: {=V9} -> Rio Mar Restaurante
B41: {=B40+1} -> 6 | C41: Velocity | D41: 50 | E41: {=G14/G28} -> 46.959401 | F41: {=E41-D41} -> -3.0405994 | U41: {=U40+1} -> 3 | V41: {=V10} -> Rio Mar Mercado
...

Sheet DRE Report
C3: REALIZADO | D3: VIABILIDADE | F3: REALIZADO | G3: VIABILIDADE | H3: REALIZADO | I3: VIABILIDADE | J3: REALIZADO | K3: VIABILIDADE | M3: REAL | N3: REAL | O3: REAL | P3: PROJ | Q3: PROJ | R3: PROJ | S3: PROJ | T3: PROJ | U3: PROJ | V3: PROJ | W3: PROJ | X3: PROJ
C4: 2025 | D4: 2026 | F4: 46023 | G4: 46023 | H4: {=I4} -> 46054 | I4: {=EDATE(F4,1)} -> 46054 | J4: {=EDATE(H4,1)} -> 46082 | K4: {=EDATE(I4,1)} -> 46082 | M4: {=F4} -> 46023 | N4: {=H4} -> 46054 | O4: {=EDATE(N4,1)} -> 46082 | P4: {=EDATE(O4,1)} -> 46113 | Q4: {=EDATE(P4,1)} -> 46143 | R4: {=EDATE(Q4,1)} -> 46174 | S4: {=EDATE(R4,1)} -> 46204 | T4: {=EDATE(S4,1)} -> 46235 | U4: {=EDATE(T4,1)} -> 46266 | V4: {=EDATE(U4,1)} -> 46296 | ... X4: {=EDATE(W4,1)} -> 46357
B5: Números de Operações | C5: 4 | D5: 7 | F5: 6 | G5: 7 | H5: {=G5} -> 7 | I5: 7 | J5: {=I5} -> 7 | K5: {=J5} -> 7 | M5: {=F5} -> 6 | N5: {=H5} -> 7 | O5: 7 | P5: {=O5} -> 7 | Q5: {=P5} -> 7 | R5: {=Q5} -> 7 | S5: {=R5} -> 7 | T5: {=S5} -> 7 | U5: {=T5} -> 7 | V5: {=U5} -> 7 | W5: {=V5} -> 7 | X5: {=W5} -> 7
B7: Receita Bruta | C7: {=SUM(C8:C15)} -> 13695103 | D7: {=SUM(D8:D15)} -> 27284247 | F7: {=SUM(F8:F15)} -> 1692201.4 | G7: 1692201.4 | H7: {=SUM(H8:H15)} -> 1276895.4 | I7: {=SUM(I8:I15)} -> 1446688.7 | J7: {=SUM(J8:J15)} -> 1494914.9 | K7: {=SUM(K8:K15)} -> 1857781.8 | M7: {=F7} -> 1692201.4 | N7: {=H7} -> 1276895.4 | O7: {=J7} -> 1494914.9 | P7: {=SUM(P8:P15)} -> 1926520.4 | Q7: {=SUM(Q8:Q15)} -> 2049259 | R7: {=SUM(R8:R15)} -> 2171997.5 | S7: {=SUM(S8:S15)} -> 2294736.1 | T7: {=SUM(T8:T15)} -> 2417474.7 | U7: {=SUM(U8:U15)} -> 2540213.2 | V7: {=SUM(V8:V15)} -> 2716951.8 | W7: {=SUM(W8:W15)} -> 2839690.3 | X7: {=SUM(X8:X15)} -> 3124428.9
B8: Rio Mar Restaurante | C8: 10389434 | D8: 12035151 | F8: 826347.48 | G8: 826347.48 | H8: 640037.49 | I8: 652500 | J8: 955297.04 | K8: 900000 | M8: {=F8} -> 826347.48 | N8: {=H8} -> 640037.49 | O8: {=J8} -> 955297.04 | P8: 930000 | Q8: 960000 | R8: 990000 | S8: 1020000 | T8: 1050000 | U8: 1080000 | V8: 1110000 | W8: 1140000 | X8: 1170000
B9: Rio Mar Mercado | C9: 2559447 | D9: 2957317.5 | F9: 206303.2 | G9: 206303.2 | H9: 161203.34 | I9: 163148.09 | J9: 83754.63 | K9: 225031.85 | M9: {=F9} -> 206303.2 | N9: {=H9} -> 161203.34 | O9: {=J9} -> 83754.63 | P9: 232532.91 | Q9: 240033.97 | R9: 247535.03 | S9: 255036.09 | T9: 262537.16 | U9: 270038.22 | V9: 277539.28 | W9: 285040.34 | X9: 292541.4
B10: Lagoa Azul | C10: 449297.42 | D10: 908065.53 | F10: 101815.53 | G10: 101815.53 | H10: 57639.62 | I10: 71250 | J10: 64098.57 | K10: 60000 | M10: {=F10} -> 101815.53 | N10: {=H10} -> 57639.62 | O10: {=J10} -> 64098.57 | P10: 63000 | Q10: 66000 | R10: 69000 | S10: 72000 | T10: 75000 | U10: 78000 | V10: 81000 | W10: 84000 | X10: 87000
B11: Velocity | C11: 120278 | D11: 750241.71 | F11: 44772.96 | G11: 44772.96 | H11: 56254.08 | I11: 62343.75 | J11: 57476.63 | K11: 52500 | M11: {=F11} -> 44772.96 | N11: {=H11} -> 56254.08 | O11: {=J11} -> 57476.63 | P11: 55125 | Q11: 57750 | R11: 60375 | S11: 63000 | T11: 65625 | U11: 68250 | V11: 70875 | W11: 73500 | X11: 76125
B12: Cabanga | C12: 150579.22 | D12: 821472.33 | F12: 65612.96 | G12: 65612.96 | H12: 40901.8 | I12: 66796.875 | J12: 258958.43 | K12: 56250 | M12: {=F12} -> 65612.96 | N12: {=H12} -> 40901.8 | O12: {=J12} -> 258958.43 | P12: 59062.5 | Q12: 61875 | R12: 64687.5 | S12: 67500 | T12: 70312.5 | U12: 73125 | V12: 75937.5 | W12: 78750 | X12: 81562.5
B13: Paiva | C13: 0 | D13: 4448179.7 | F13: 425179.73 | G13: 425179.73 | H13: 296516 | I13: 405000 | J13: 22390.94 | K13: 378000 | M13: {=F13} -> 425179.73 | N13: {=H13} -> 296516 | O13: {=J13} -> 22390.94 | P13: 324000 | Q13: 324000 | R13: 324000 | S13: 324000 | T13: 324000 | U13: 324000 | V13: 378000 | W13: 378000 | X13: 540000
B14: Maison | C14: 26067 | D14: 488819.59 | F14: 22169.59 | G14: 22169.59 | H14: 24343.08 | I14: 25650 | J14: 52938.71 | K14: 36000 | M14: {=F14} -> 22169.59 | N14: {=H14} -> 24343.08 | O14: {=J14} -> 52938.71 | P14: 37800 | Q14: 39600 | R14: 41400 | S14: 43200 | T14: 45000 | U14: 46800 | V14: 48600 | W14: 50400 | X14: 52200
B15: Cozinha Central / Delivery | C15: 0 | D15: 4875000 | F15: 0 | G15: 0 | H15: 0 | I15: 0 | J15: 0 | K15: 150000 | M15: {=F15} -> 0 | N15: {=H15} -> 0 | O15: {=J15} -> 0 | P15: 225000 | Q15: 300000 | R15: 375000 | S15: 450000 | T15: 525000 | U15: 600000 | V15: 675000 | W15: 750000 | X15: 825000
B16: (-) Deduções da Receita | C16: -1496546 | D16: -3085122.5 | F16: -245572.01 | G16: {=F16} -> -245572.01 | H16: -196034.61 | I16: -193259.23 | J16: -253812.67 | K16: -164802.19 | M16: {=F16} -> -245572.01 | N16: {=H16} -> -196034.61 | O16: {=J16} -> -253812.67 | P16: -211632.62 | Q16: -219463.1 | R16: -233445.08 | S16: -247427.07 | T16: -261409.06 | U16: -275391.05 | V16: -289373.03 | W16: -309506.53 | X16: -323488.52
B17: Receita Líquida | C17: {=C16+C7} -> 12198557 | D17: {=D16+D7} -> 24199125 | F17: {=F16+F7} -> 1446629.4 | G17: {=G16+G7} -> 1446629.4 | H17: {=H16+H7} -> 1080860.8 | I17: {=I16+I7} -> 1253429.5 | J17: {=J16+J7} -> 1241102.3 | K17: {=K16+K7} -> 1692979.7 | M17: {=F17} -> 1446629.4 | N17: {=H17} -> 1080860.8 | O17: {=J17} -> 1241102.3 | P17: {=P16+P7} -> 1714887.8 | Q17: {=Q16+Q7} -> 1829795.9 | R17: {=R16+R7} -> 1938552.4 | S17: {=S16+S7} -> 2047309 | T17: {=T16+T7} -> 2156065.6 | U17: {=U16+U7} -> 2264822.2 | V17: {=V16+V7} -> 2427578.7 | W17: {=W16+W7} -> 2530183.8 | X17: {=X16+X7} -> 2800940.4
B18: (-) CMV | C18: -4019615.9 | D18: -6295541.4 | F18: -508299.97 | G18: -462085.14 | H18: -396373.37 | I18: -336217.36 | J18: -479655.99 | K18: -428562.74 | M18: {=F18} -> -508299.97 | N18: {=H18} -> -396373.37 | O18: {=J18} -> -479655.99 | P18: -444410.66 | Q18: -471058.59 | R18: -497706.51 | S18: -524354.44 | T18: -551002.36 | U18: -577650.29 | V18: -615098.21 | W18: -641746.14 | X18: -700794.06
B19: CMV % | C19: {=C18/C7} -> -0.29350753 | D19: {=D18/D7} -> -0.23073906 | F19: {=F18/F7} -> -0.30037793 | G19: {=G18/G7} -> -0.27306745 | H19: {=H18/H7} -> -0.31041961 | I19: {=I18/I7} -> -0.23240477 | J19: {=J18/J7} -> -0.32085838 | K19: {=K18/K7} -> -0.23068518 | M19: {=F19} -> -0.30037793 | N19: {=H19} -> -0.31041961 | O19: {=J19} -> -0.32085838 | P19: {=P18/P7} -> -0.23068049 | Q19: {=Q18/Q7} -> -0.22986777 | R19: {=R18/R7} -> -0.22914691 | S19: {=S18/S7} -> -0.22850316 | T19: {=T18/T7} -> -0.22792477 | U19: {=U18/U7} -> -0.22740228 | V19: {=V18/V7} -> -0.22639276 | W19: {=W18/W7} -> -0.22599159 | X19: {=X18/X7} -> -0.22429509
B20: Lucro Bruto | C20: {=C18+C17} -> 8178941.1 | D20: {=D18+D17} -> 17903583 | F20: {=F18+F17} -> 938329.47 | G20: {=G18+G17} -> 984544.31 | H20: {=H18+H17} -> 684487.43 | I20: {=I18+I17} -> 917212.12 | J20: {=J18+J17} -> 761446.29 | K20: {=K18+K17} -> 1264416.9 | M20: {=F20} -> 938329.47 | N20: {=H20} -> 684487.43 | O20: {=J20} -> 761446.29 | P20: {=P18+P17} -> 1270477.1 | Q20: {=Q18+Q17} -> 1358737.3 | R20: {=R18+R17} -> 1440845.9 | S20: {=S18+S17} -> 1522954.6 | T20: {=T18+T17} -> 1605063.2 | U20: {=U18+U17} -> 1687171.9 | V20: {=V18+V17} -> 1812480.5 | W20: {=W18+W17} -> 1888437.7 | X20: {=X18+X17} -> 2100146.3
B21: (-) Despesas Operacionais | C21: {=C22+C23} -> -8287581.7 | D21: {=D22+D23} -> -11802675 | F21: {=F22+F23} -> -1173111.8 | G21: {=G22+G23} -> -899741.44 | H21: {=H22+H23} -> -875908.68 | I21: {=I22+I23} -> -889465.96 | J21: {=J22+J23} -> -1340172.7 | K21: {=K22+K23} -> -959985.58 | M21: {=M22+M23} -> -1173111.8 | N21: {=N22+N23} -> -875908.68 | O21: {=O22+O23} -> -1329899.7 | P21: {=P22+P23} -> -998917.43 | Q21: {=Q22+Q23} -> -1027595.2 | R21: {=R22+R23} -> -1053022.9 | S21: {=S22+S23} -> -1078450.6 | T21: {=T22+T23} -> -1103878.4 | ... X21: {=X22+X23} -> -1235935.4
B22: Despesas com Pessoal | C22: -4624228.8 | D22: -6178277 | F22: -607518.41 | G22: -554503.25 | H22: -493099.73 | I22: -544680.52 | J22: -503372.77 | K22: -561124.25 | M22: -607518.41 | N22: -493099.73 | O22: -493099.73 | P22: -584964.44 | Q22: -593123.98 | R22: -598033.52 | S22: -602943.07 | T22: -607852.61 | U22: -612762.15 | V22: -619831.69 | W22: -624741.24 | X22: -636130.78
B23: Despesas Gerais | C23: {=SUM(C24:C39)} -> -3663352.8 | D23: {=SUM(D24:D39)} -> -5624398.4 | F23: {=SUM(F24:F39)} -> -565593.41 | G23: {=SUM(G24:G39)} -> -345238.18 | H23: {=SUM(H24:H39)} -> -382808.95 | I23: {=SUM(I24:I39)} -> -344785.44 | J23: {=SUM(J24:J39)} -> -836799.94 | K23: {=SUM(K24:K39)} -> -398861.33 | M23: {=F23} -> -565593.41 | N23: {=H23} -> -382808.95 | O23: {=J23} -> -836799.94 | P23: {=SUM(P24:P39)} -> -413952.99 | Q23: {=SUM(Q24:Q39)} -> -434471.18 | R23: {=SUM(R24:R39)} -> -454989.37 | S23: {=SUM(S24:S39)} -> -475507.55 | T23: {=SUM(T24:T39)} -> -496025.74 | U23: {=SUM(U24:U39)} -> -516543.93 | V23: {=SUM(V24:V39)} -> -542488.65 | W23: {=SUM(W24:W39)} -> -563006.83 | X23: {=SUM(X24:X39)} -> -599804.6
B24: Aluguel Condomínio | C24: -1623234.1 | D24: -1943639.7 | F24: -138640.07 | G24: -159466.98 | H24: -137404.51 | I24: -177947.56 | J24: -151059.7 | K24: -173863.34 | M24: {=F24} -> -138640.07 | N24: {=H24} -> -137404.51 | O24: {=J24} -> -151059.7 | P24: -171892.47 | Q24: -172621.59 | R24: -173350.72 | S24: -174079.84 | T24: -174808.97 | U24: -175538.09 | V24: -178967.22 | W24: -179696.34 | X24: -188525.47
B25: Serviços de Limpesa Tercerizados | C25: -175409.34 | D25: -233483.68 | F25: -13483.68 | G25: -20000 | H25: 0 | I25: -20000 | J25: 0 | K25: -20000 | M25: {=F25} -> -13483.68 | N25: {=H25} -> 0 | O25: {=J25} -> 0 | P25: -20000 | Q25: -20000 | R25: -20000 | S25: -20000 | T25: -20000 | U25: -20000 | V25: -20000 | W25: -20000 | X25: -20000
B26: Prestadores de Serviço Gerais | C26: -734395.88 | D26: -1051310.6 | F26: -227273.22 | G26: -61962.375 | H26: -124981.23 | I26: -48938.885 | J26: -361486.58 | K26: -67501.911 | M26: {=F26} -> -227273.22 | N26: {=H26} -> -124981.23 | O26: {=J26} -> -361486.58 | P26: -69751.975 | Q26: -72002.038 | R26: -74252.102 | S26: -76502.166 | T26: -78752.229 | U26: -81002.293 | V26: -83252.357 | W26: -85502.42 | X26: -87752.484
B27: Marketing | C27: -53342.62 | D27: -258470.64 | F27: -4613.22 | G27: -16922.57 | H27: -156.46 | I27: -14466.887 | J27: -2203.68 | K27: -18577.818 | M27: {=F27} -> -4613.22 | N27: {=H27} -> -156.46 | O27: {=J27} -> -2203.68 | P27: -19265.204 | Q27: -20492.59 | R27: -21719.975 | S27: -22947.361 | T27: -24174.747 | U27: -25402.132 | V27: -27169.518 | W27: -28396.903 | X27: -31244.289
B28: Taxa Máquina Cartão | C28: -251027.87 | D28: -454179.48 | F28: -48965.42 | G28: -29106.821 | H28: -37448.66 | I28: -24883.046 | J28: -14400.94 | K28: -31953.848 | M28: {=F28} -> -48965.42 | N28: {=H28} -> -37448.66 | O28: {=J28} -> -14400.94 | P28: -33136.151 | Q28: -35247.254 | R28: -37358.358 | S28: -39469.461 | T28: -41580.564 | U28: -43691.667 | V28: -46731.571 | W28: -48842.674 | X28: -53740.177
B29: Taxa Ifood | C29: -270874.06 | D29: -837630.85 | F29: -15317.94 | G29: -9009.1411 | H29: -11598.87 | I29: -10058.737 | J29: 0 | K29: -31461.592 | M29: {=F29} -> -15317.94 | N29: {=H29} -> -11598.87 | O29: {=J29} -> 0 | P29: -42190.739 | Q29: -53637.614 | R29: -65084.489 | S29: -76531.364 | T29: -87978.239 | U29: -99425.114 | V29: -111589.72 | W29: -123036.59 | X29: -136636.65
B30: Embalagens e acessórios | C30: -110804.24 | D30: -374196.33 | F30: -15784.22 | G30: -17370.3 | H30: -17749.93 | I30: -15090.325 | J30: -39286.13 | K30: -22102.818 | M30: {=F30} -> -15784.22 | N30: {=H30} -> -17749.93 | O30: {=J30} -> -39286.13 | P30: -24316.454 | Q30: -27070.09 | R30: -29823.725 | S30: -32577.361 | T30: -35330.997 | U30: -38084.632 | V30: -41378.268 | W30: -44131.903 | X30: -48505.539
B31: Carreto e Fretes | C31: -15152.92 | D31: -26353.98 | F31: -4353.98 | G31: -2000 | H31: -1384.35 | I31: -2000 | J31: -180.61 | K31: -2000 | M31: {=F31} -> -4353.98 | N31: {=H31} -> -1384.35 | O31: {=J31} -> -180.61 | P31: -2000 | Q31: -2000 | R31: -2000 | S31: -2000 | T31: -2000 | U31: -2000 | V31: -2000 | W31: -2000 | X31: -2000
B32: Telefonia | C32: -26523.3 | D32: -62010.42 | F32: -18010.42 | G32: -3500 | H32: -5625.31 | I32: -4000 | J32: -6298.03 | K32: -4000 | M32: {=F32} -> -18010.42 | N32: {=H32} -> -5625.31 | O32: {=J32} -> -6298.03 | P32: -4000 | Q32: -4000 | R32: -4000 | S32: -4000 | T32: -4000 | U32: -4000 | V32: -4000 | W32: -4000 | X32: -4000
B33: Manutenção | C33: -89827.13 | D33: -121999.45 | F33: -33999.45 | G33: -8000 | H33: -11822.54 | I33: -8000 | J33: -17958.73 | K33: -8000 | M33: {=F33} -> -33999.45 | N33: {=H33} -> -11822.54 | O33: {=J33} -> -17958.73 | P33: -8000 | Q33: -8000 | R33: -8000 | S33: -8000 | T33: -8000 | U33: -8000 | V33: -8000 | W33: -8000 | X33: -8000
B34: Material para uso e consumo | C34: -92986.85 | D34: -90127.02 | F34: -27942.26 | G34: -4500 | H34: -11779.6 | I34: -5000 | J34: -59306.36 | K34: -5000 | M34: {=F34} -> -27942.26 | N34: {=H34} -> -11779.6 | O34: {=J34} -> -59306.36 | P34: -5000 | Q34: -5000 | R34: -5000 | S34: -5000 | T34: -5000 | U34: -5000 | V34: -5000 | W34: -5000 | X34: -5000
B35: Contabilidade | C35: -64203.72 | D35: -68931.68 | F35: -8431.68 | G35: -5000 | H35: -5431.68 | I35: -5500 | J35: -5504.6 | K35: -5500 | M35: {=F35} -> -8431.68 | N35: {=H35} -> -5431.68 | O35: {=J35} -> -5504.6 | P35: -5500 | Q35: -5500 | R35: -5500 | S35: -5500 | T35: -5500 | U35: -5500 | V35: -5500 | W35: -5500 | X35: -5500
... B40: (-) Depreciação e Amortização | C40: -348485.52 | D40: -348485.52 | F40: -29040.46 | G40: -31666.667 | H40: -29040.46 | I40: -29040.46 | J40: -29040.46 | K40: -29040.46 | M40: {=F40} -> -29040.46 | N40: {=H40} -> -29040.46 | O40: {=J40} -> -29040.46 | P40: -29040.46 | Q40: -29040.46 | R40: -29040.46 | S40: -29040.46 | T40: -29040.46 | U40: -29040.46 | V40: -29040.46 | W40: -29040.46 | X40: -29040.46
B41: EBITDA | C41: {=C21+C20+C40} -> -457126.12 | D41: {=D21+D20+D40} -> 5752422.3 | F41: {=F21+F20} -> -234782.35 | G41: {=G21+G20} -> 84802.868 | H41: {=H21+H20} -> -191421.25 | I41: {=I21+I20} -> 27746.159 | J41: {=J21+J20} -> -578726.42 | K41: {=K21+K20} -> 304431.34 | M41: {=F41} -> -234782.35 | N41: {=H41} -> -191421.25 | O41: {=J41} -> -578726.42 | P41: {=P21+P20} -> 271559.7 | Q41: {=Q21+Q20} -> 331142.13 | R41: {=R21+R20} -> 387823.05 | S41: {=S21+S20} -> 444503.96 | T41: {=T21+T20} -> 501184.88 | U41: {=U21+U20} -> 557865.8 | V41: {=V21+V20} -> 650160.19 | W41: {=W21+W20} -> 700689.6 | X41: {=X21+X20} -> 864210.94
B42: Mg EBITDA | C42: {=C41/C17} -> -0.037473787 | D42: {=D41/D17} -> 0.237712 | F42: {=F41/F17} -> -0.16229612 | G42: {=G41/G17} -> 0.058621003 | H42: {=H41/H17} -> -0.17710074 | I42: {=I41/I17} -> 0.022136195 | J42: {=J41/J17} -> -0.46630034 | K42: {=K41/K17} -> 0.17981985 | M42: {=F42} -> -0.16229612 | N42: {=H42} -> -0.17710074 | O42: {=J42} -> -0.46630034 | P42: {=P41/P17} -> 0.15835421 | Q42: {=Q41/Q17} -> 0.18097217 | R42: {=R41/R17} -> 0.20005806 | S42: {=S41/S17} -> 0.2171162 | T42: {=T41/T17} -> 0.23245345 | U42: {=U41/U17} -> 0.24631771 | V42: {=V41/V17} -> 0.26782249 | W42: {=W41/W17} -> 0.27693229 | X42: {=X41/X17} -> 0.30854314
B43: (-) Resultado Financeiro | C43: {=SUM(C44:C45)} -> -256083.08 | D43: {=SUM(D44:D45)} -> -1633729.1 | F43: {=SUM(F44:F45)} -> -16114.93 | G43: {=SUM(G44:G45)} -> -193943.87 | H43: {=SUM(H44:H45)} -> -23514.01 | I43: {=SUM(I44:I45)} -> -189599.31 | J43: {=SUM(J44:J45)} -> -251746.08 | K43: {=SUM(K44:K45)} -> -222366.9 | M43: {=F43} -> -16114.93 | N43: {=H43} -> -23514.01 | O43: {=J43} -> -251746.08 | P43: {=SUM(P44:P45)} -> -222366.9 | Q43: {=SUM(Q44:Q45)} -> -196054.91 | R43: {=SUM(R44:R45)} -> -195508.98 | S43: {=SUM(S44:S45)} -> -194963.04 | T43: {=SUM(T44:T45)} -> -194417.1 | U43: {=SUM(U44:U45)} -> -193871.16 | V43: {=SUM(V44:V45)} -> -193325.22 | W43: {=SUM(W44:W45)} -> -192779.29 | X43: {=SUM(X44:X45)} -> -192233.35
B44: Despesas Financeiras | C44: -256083.08 | D44: -1633729.1 | F44: -16114.93 | G44: -193943.87 | H44: -23514.01 | I44: -189599.31 | J44: -251746.08 | K44: -222366.9 | M44: {=F44} -> -16114.93 | N44: {=H44} -> -23514.01 | O44: {=J44} -> -251746.08 | P44: -222366.9 | Q44: -196054.91 | R44: -195508.98 | S44: -194963.04 | T44: -194417.1 | U44: -193871.16 | V44: -193325.22 | W44: -192779.29 | X44: -192233.35
B45: Receita Financeira | C45: 0 | D45: 0 | F45: 0 | G45: 0 | H45: 0 | I45: 0 | J45: 0 | K45: 0 | M45: {=F45} -> 0 | N45: {=H45} -> 0 | O45: {=J45} -> 0 | P45: 0 | Q45: 0 | R45: 0 | S45: 0 | T45: 0 | U45: 0 | V45: 0 | W45: 0 | X45: 0
B46: LAIR | C46: {=C41+C40+C43} -> -1061694.7 | D46: {=D41+D40+D43} -> 3770207.7 | F46: {=F41+F40+F43} -> -279937.74 | G46: {=G41+G40+G43} -> -140807.67 | H46: {=H41+H40+H43} -> -243975.72 | I46: {=I41+I40+I43} -> -190893.61 | J46: {=J41+J40+J43} -> -859512.96 | K46: {=K41+K40+K43} -> 53023.979 | M46: {=F46} -> -279937.74 | N46: {=H46} -> -243975.72 | O46: {=J46} -> -859512.96 | P46: {=P41+P40+P43} -> 20152.338 | Q46: {=Q41+Q40+Q43} -> 106046.75 | R46: {=R41+R40+R43} -> 163273.61 | S46: {=S41+S40+S43} -> 220500.47 | T46: {=T41+T40+T43} -> 277727.32 | U46: {=U41+U40+U43} -> 334954.18 | V46: {=V41+V40+V43} -> 427794.51 | W46: {=W41+W40+W43} -> 478869.86 | X46: {=X41+X40+X43} -> 642937.13
B47: (-) CSLL / IRPJ | C47: -377969.39 | D47: {=-D46*34%} -> -1281870.6 | F47: -38630.8 | G47: 0 | H47: 0 | I47: 0 | M47: {=F47} -> -38630.8 | N47: {=H47} -> 0 | O47: {=J47} -> 0 | P47: 0 | Q47: 0 | R47: -183351.53 | S47: 0 | T47: 0 | U47: -217374.66 | V47: 0 | W47: 0 | X47: -261376.99
...

Sheet Comparativo
B2: 46023
B3: Rateio / Receita | C3: 0.61024099 | E3: 0.25125834 | G3: 0.02645841 | I3: 0.038773729 | K3: 0.0601675 | M3: 0.013101035 | O3: {=O5/$O$5} -> 1
C4: Rio Mar | E4: Paiva | G4: Velocity | I4: Cabanga | K4: Lagoa | M4: Maison | O4: Consolidado
B5: Receita Bruta | C5: 1032650.7 | E5: 425179.73 | G5: 44772.96 | I5: 65612.96 | K5: 101815.53 | M5: 22169.59 | O5: {=C5+E5+G5+I5+K5+M5} -> 1692201.4
B6: (-) Deduções da Receita | C6: -117949.06 | D6: {=C6/C$5} -> -0.11421971 | E6: -48561.291 | F6: {=E6/E$5} -> -0.11421356 | G6: -5113.6792 | H6: {=G6/G$5} -> -0.11421356 | I6: -7474.4203 | J6: {=I6/I$5} -> -0.11391683 | K6: -11628.714 | L6: {=K6/K$5} -> -0.11421356 | M6: -2532.0678 | N6: {=M6/M$5} -> -0.11421356 | O6: {='DRE Report'!F16} -> -245572.01 | P6: {=O6/O$5} -> -0.14511984
B7: Receita Líquida | C7: {=C6+C5} -> 914701.62 | D7: {=C7/C$5} -> 0.88578029 | E7: {=E6+E5} -> 376618.44 | F7: {=E7/E$5} -> 0.88578644 | G7: {=G6+G5} -> 39659.281 | H7: {=G7/G$5} -> 0.88578644 | I7: {=I6+I5} -> 58138.54 | J7: {=I7/I$5} -> 0.88608317 | K7: {=K6+K5} -> 90186.816 | L7: {=K7/K$5} -> 0.88578644 | M7: {=M6+M5} -> 19637.522 | N7: {=M7/M$5} -> 0.88578644 | O7: {=O5+O6} -> 1446629.4 | P7: {=O7/O$5} -> 0.85488016
B8: (-) CMV / CPV | C8: -347025.94 | D8: {=C8/C$5} -> -0.33605356 | E8: -112267.6 | F8: {=E8/E$5} -> -0.26404739 | G8: -13484.75 | H8: {=G8/G$5} -> -0.30118067 | I8: -13122.592 | J8: {=I8/I$5} -> -0.2 | K8: -16605.24 | L8: {=K8/K$5} -> -0.16309143 | M8: -4433.918 | N8: {=M8/M$5} -> -0.2 | O8: {='DRE Report'!F18} -> -508299.97 | P8: {=O8/O$5} -> -0.30037793
B9: Lucro Bruto | C9: 567675.68 | D9: {=C9/C$5} -> 0.54972673 | E9: {=E7+E8} -> 264350.84 | F9: {=E9/E$5} -> 0.62173904 | G9: {=G7+G8} -> 26174.531 | H9: {=G9/G$5} -> 0.58460577 | I9: {=I7+I8} -> 45015.948 | J9: {=I9/I$5} -> 0.68608317 | K9: {=K7+K8} -> 73581.576 | L9: {=K9/K$5} -> 0.72269501 | M9: {=M7+M8} -> 15203.604 | N9: {=M9/M$5} -> 0.68578644 | O9: {=O7+O8} -> 938329.47 | P9: {=O9/O$5} -> 0.55450223
B10: Total Despesas Gerais | C10: -332875.72 | D10: {=C10/C$5} -> -0.32235075 | E10: -96473.351 | F10: {=E10/E$5} -> -0.22690017 | G10: -10158.992 | H10: {=G10/G$5} -> -0.22690017 | I10: -14887.592 | J10: {=I10/I$5} -> -0.22690017 | K10: -23101.961 | L10: {=K10/K$5} -> -0.22690017 | M10: -5030.2837 | N10: {=M10/M$5} -> -0.22690017 | O10: {='DRE Report'!F23} -> -565593.41 | P10: {=O10/O$5} -> -0.33423527
B11: Total Head Count | C11: -481930.15 | D11: {=C11/C$5} -> -0.46669233 | E11: -32258.485 | F11: {=E11/E$5} -> -0.075870233 | G11: -15931.791 | H11: {=G11/G$5} -> -0.35583512 | I11: -14582.327 | J11: {=I11/I$5} -> -0.22224766 | K11: -18358.106 | L11: {=K11/K$5} -> -0.18030752 | M11: -3986.3838 | N11: {=M11/M$5} -> -0.17981315 | O11: {='DRE Report'!F22} -> -607518.41 | P11: {=O11/O$5} -> -0.35901069
B12: EBITDA | C12: {=C9+C11+C10} -> -247130.19 | D12: {=C12/C$5} -> -0.23931635 | E12: {=E9+E11+E10} -> 135619 | F12: {=E12/E$5} -> 0.31896864 | G12: {=G9+G11+G10} -> 83.747232 | H12: {=G12/G$5} -> 0.0018704868 | I12: {=I9+I11+I10} -> 15546.029 | J12: {=I12/I$5} -> 0.23693535 | K12: {=K9+K11+K10} -> 32121.509 | L12: {=K12/K$5} -> 0.31548733 | M12: {=M9+M11+M10} -> 6186.9367 | N12: {=M12/M$5} -> 0.27907312 | O12: {=O9+O10+O11} -> -234782.35 | P12: {=O12/O$5} -> -0.13874374

Sheet References
C3: References | P3: {=TODAY()} -> 46143
A6: x | C6: References | Q6: x
C8: Weekdays | D8: Eng | E8: Port | G8: Cor | H8: Referencia
C9: 1 | D9: S | E9: Domingo | G9: Azul | H9: .
C10: {=C9+1} -> 2 | D10: M | E10: Segunda | G10: Amarelo | H10: ..
C11: {=C10+1} -> 3 | D11: T | E11: Terça | G11: Laranja | H11: ...
C12: {=C11+1} -> 4 | D12: W | E12: Quarta | G12: Vermelho | H12: ....
C13: {=C12+1} -> 5 | D13: T | E13: Quinta
C14: {=C13+1} -> 6 | D14: F | E14: Sexta
C15: {=C14+1} -> 7 | D15: S | E15: Sábado
